package sorcery.world;

import java.util.Random;

import net.minecraft.block.Block;
import net.minecraft.init.Blocks;
import net.minecraft.world.World;
import net.minecraft.world.gen.feature.WorldGenerator;

public class WorldGenTestificateHead extends WorldGenerator {
	protected Block[] GetValidSpawnBlocks() {
		return new Block[]{Blocks.stone, Blocks.grass, Blocks.dirt, Blocks.sand, Blocks.sandstone, Blocks.snow};
	}
	
	public boolean LocationIsValidSpawn(World world, int i, int j, int k) {
		int distanceToAir = 0;
		Block checkID = world.getBlock(i, j, k);
		
		while(!checkID.isAir(world, i, j, k)) {
			distanceToAir++;
			checkID = world.getBlock(i, j + distanceToAir, k);
		}
		
		if(distanceToAir > 8) {
			return false;
		}
		j += distanceToAir - 1;
		
		Block blockID = world.getBlock(i, j, k);
		Block blockIDAbove = world.getBlock(i, j + 1, k);
		Block blockIDBelow = world.getBlock(i, j - 1, k);
		for(Block x : GetValidSpawnBlocks()) {
			if(blockIDAbove.isAir(world, i, j, k)) {
				return false;
			}
			if(blockID == x) {
				return true;
			} else if(blockID == Blocks.snow && blockIDBelow == x) {
				return true;
			}
		}
		return false;
	}
	
	public WorldGenTestificateHead() {
	}
	
	public boolean generate(World world, Random rand, int i, int j, int k) {
		// check that each corner is one of the valid spawn blocks
		if(!LocationIsValidSpawn(world, i, j, k) || !LocationIsValidSpawn(world, i + 9, j, k) || !LocationIsValidSpawn(world, i + 9, j, k + 9) || !LocationIsValidSpawn(world, i, j, k + 9)) {
			return false;
		}
		
		world.setBlock(i + 1, j + 4, k + 1, pickBlockToUse(rand), 0, 2);
		world.setBlock(i + 1, j + 4, k + 2, pickBlockToUse(rand), 0, 2);
		world.setBlock(i + 1, j + 4, k + 3, pickBlockToUse(rand), 0, 2);
		world.setBlock(i + 1, j + 4, k + 4, pickBlockToUse(rand), 0, 2);
		world.setBlock(i + 1, j + 4, k + 5, pickBlockToUse(rand), 0, 2);
		world.setBlock(i + 1, j + 4, k + 6, pickBlockToUse(rand), 0, 2);
		world.setBlock(i + 1, j + 4, k + 7, pickBlockToUse(rand), 0, 2);
		world.setBlock(i + 1, j + 4, k + 8, pickBlockToUse(rand), 0, 2);
		world.setBlock(i + 1, j + 5, k + 1, pickBlockToUse(rand), 0, 2);
		world.setBlock(i + 1, j + 5, k + 2, pickBlockToUse(rand), 0, 2);
		world.setBlock(i + 1, j + 5, k + 3, pickBlockToUse(rand), 0, 2);
		world.setBlock(i + 1, j + 5, k + 4, pickBlockToUse(rand), 0, 2);
		world.setBlock(i + 1, j + 5, k + 5, pickBlockToUse(rand), 0, 2);
		world.setBlock(i + 1, j + 5, k + 6, pickBlockToUse(rand), 0, 2);
		world.setBlock(i + 1, j + 5, k + 7, pickBlockToUse(rand), 0, 2);
		world.setBlock(i + 1, j + 5, k + 8, pickBlockToUse(rand), 0, 2);
		world.setBlock(i + 1, j + 6, k + 1, pickBlockToUse(rand), 0, 2);
		world.setBlock(i + 1, j + 6, k + 2, pickBlockToUse(rand), 0, 2);
		world.setBlock(i + 1, j + 6, k + 3, pickBlockToUse(rand), 0, 2);
		world.setBlock(i + 1, j + 6, k + 4, pickBlockToUse(rand), 0, 2);
		world.setBlock(i + 1, j + 6, k + 5, pickBlockToUse(rand), 0, 2);
		world.setBlock(i + 1, j + 6, k + 6, pickBlockToUse(rand), 0, 2);
		world.setBlock(i + 1, j + 6, k + 7, pickBlockToUse(rand), 0, 2);
		world.setBlock(i + 1, j + 6, k + 8, pickBlockToUse(rand), 0, 2);
		world.setBlock(i + 1, j + 7, k + 1, pickBlockToUse(rand), 0, 2);
		world.setBlock(i + 1, j + 7, k + 2, pickBlockToUse(rand), 0, 2);
		world.setBlock(i + 1, j + 7, k + 3, pickBlockToUse(rand), 0, 2);
		world.setBlock(i + 1, j + 7, k + 4, pickBlockToUse(rand), 0, 2);
		world.setBlock(i + 1, j + 7, k + 5, pickBlockToUse(rand), 0, 2);
		world.setBlock(i + 1, j + 7, k + 6, pickBlockToUse(rand), 0, 2);
		world.setBlock(i + 1, j + 7, k + 7, pickBlockToUse(rand), 0, 2);
		world.setBlock(i + 1, j + 7, k + 8, pickBlockToUse(rand), 0, 2);
		world.setBlock(i + 1, j + 8, k + 1, pickBlockToUse(rand), 0, 2);
		world.setBlock(i + 1, j + 8, k + 2, pickBlockToUse(rand), 0, 2);
		world.setBlock(i + 1, j + 8, k + 3, pickBlockToUse(rand), 0, 2);
		world.setBlock(i + 1, j + 8, k + 4, pickBlockToUse(rand), 0, 2);
		world.setBlock(i + 1, j + 8, k + 5, pickBlockToUse(rand), 0, 2);
		world.setBlock(i + 1, j + 8, k + 6, pickBlockToUse(rand), 0, 2);
		world.setBlock(i + 1, j + 8, k + 7, pickBlockToUse(rand), 0, 2);
		world.setBlock(i + 1, j + 8, k + 8, pickBlockToUse(rand), 0, 2);
		world.setBlock(i + 1, j + 9, k + 1, pickBlockToUse(rand), 0, 2);
		world.setBlock(i + 1, j + 9, k + 2, pickBlockToUse(rand), 0, 2);
		world.setBlock(i + 1, j + 9, k + 3, pickBlockToUse(rand), 0, 2);
		world.setBlock(i + 1, j + 9, k + 4, pickBlockToUse(rand), 0, 2);
		world.setBlock(i + 1, j + 9, k + 5, pickBlockToUse(rand), 0, 2);
		world.setBlock(i + 1, j + 9, k + 6, pickBlockToUse(rand), 0, 2);
		world.setBlock(i + 1, j + 9, k + 7, pickBlockToUse(rand), 0, 2);
		world.setBlock(i + 1, j + 9, k + 8, pickBlockToUse(rand), 0, 2);
		world.setBlock(i + 1, j + 10, k + 1, pickBlockToUse(rand), 0, 2);
		world.setBlock(i + 1, j + 10, k + 2, pickBlockToUse(rand), 0, 2);
		world.setBlock(i + 1, j + 10, k + 3, pickBlockToUse(rand), 0, 2);
		world.setBlock(i + 1, j + 10, k + 4, pickBlockToUse(rand), 0, 2);
		world.setBlock(i + 1, j + 10, k + 5, pickBlockToUse(rand), 0, 2);
		world.setBlock(i + 1, j + 10, k + 6, pickBlockToUse(rand), 0, 2);
		world.setBlock(i + 1, j + 10, k + 7, pickBlockToUse(rand), 0, 2);
		world.setBlock(i + 1, j + 10, k + 8, pickBlockToUse(rand), 0, 2);
		world.setBlock(i + 1, j + 11, k + 1, pickBlockToUse(rand), 0, 2);
		world.setBlock(i + 1, j + 11, k + 2, pickBlockToUse(rand), 0, 2);
		world.setBlock(i + 1, j + 11, k + 3, pickBlockToUse(rand), 0, 2);
		world.setBlock(i + 1, j + 11, k + 4, pickBlockToUse(rand), 0, 2);
		world.setBlock(i + 1, j + 11, k + 5, pickBlockToUse(rand), 0, 2);
		world.setBlock(i + 1, j + 11, k + 6, pickBlockToUse(rand), 0, 2);
		world.setBlock(i + 1, j + 11, k + 7, pickBlockToUse(rand), 0, 2);
		world.setBlock(i + 1, j + 11, k + 8, pickBlockToUse(rand), 0, 2);
		world.setBlock(i + 1, j + 12, k + 1, pickBlockToUse(rand), 0, 2);
		world.setBlock(i + 1, j + 12, k + 2, pickBlockToUse(rand), 0, 2);
		world.setBlock(i + 1, j + 12, k + 3, pickBlockToUse(rand), 0, 2);
		world.setBlock(i + 1, j + 12, k + 4, pickBlockToUse(rand), 0, 2);
		world.setBlock(i + 1, j + 12, k + 5, pickBlockToUse(rand), 0, 2);
		world.setBlock(i + 1, j + 12, k + 6, pickBlockToUse(rand), 0, 2);
		world.setBlock(i + 1, j + 12, k + 7, pickBlockToUse(rand), 0, 2);
		world.setBlock(i + 1, j + 12, k + 8, pickBlockToUse(rand), 0, 2);
		world.setBlock(i + 1, j + 13, k + 1, pickBlockToUse(rand), 0, 2);
		world.setBlock(i + 1, j + 13, k + 2, pickBlockToUse(rand), 0, 2);
		world.setBlock(i + 1, j + 13, k + 3, pickBlockToUse(rand), 0, 2);
		world.setBlock(i + 1, j + 13, k + 4, pickBlockToUse(rand), 0, 2);
		world.setBlock(i + 1, j + 13, k + 5, pickBlockToUse(rand), 0, 2);
		world.setBlock(i + 1, j + 13, k + 6, pickBlockToUse(rand), 0, 2);
		world.setBlock(i + 1, j + 13, k + 7, pickBlockToUse(rand), 0, 2);
		world.setBlock(i + 1, j + 13, k + 8, pickBlockToUse(rand), 0, 2);
		world.setBlock(i + 2, j + 4, k + 1, pickBlockToUse(rand), 0, 2);
		world.setBlock(i + 2, j + 4, k + 2, pickBlockToUse(rand), 0, 2);
		world.setBlock(i + 2, j + 4, k + 3, pickBlockToUse(rand), 0, 2);
		world.setBlock(i + 2, j + 4, k + 4, pickBlockToUse(rand), 0, 2);
		world.setBlock(i + 2, j + 4, k + 5, pickBlockToUse(rand), 0, 2);
		world.setBlock(i + 2, j + 4, k + 6, pickBlockToUse(rand), 0, 2);
		world.setBlock(i + 2, j + 4, k + 7, pickBlockToUse(rand), 0, 2);
		world.setBlock(i + 2, j + 4, k + 8, pickBlockToUse(rand), 0, 2);
		world.setBlock(i + 2, j + 5, k + 1, pickBlockToUse(rand), 0, 2);
		world.setBlock(i + 2, j + 5, k + 2, pickBlockToUse(rand), 0, 2);
		world.setBlock(i + 2, j + 5, k + 3, pickBlockToUse(rand), 0, 2);
		world.setBlock(i + 2, j + 5, k + 4, pickBlockToUse(rand), 0, 2);
		world.setBlock(i + 2, j + 5, k + 5, pickBlockToUse(rand), 0, 2);
		world.setBlock(i + 2, j + 5, k + 6, pickBlockToUse(rand), 0, 2);
		world.setBlock(i + 2, j + 5, k + 7, pickBlockToUse(rand), 0, 2);
		world.setBlock(i + 2, j + 5, k + 8, pickBlockToUse(rand), 0, 2);
		world.setBlock(i + 2, j + 6, k + 1, pickBlockToUse(rand), 0, 2);
		world.setBlock(i + 2, j + 6, k + 2, pickBlockToUse(rand), 0, 2);
		world.setBlock(i + 2, j + 6, k + 3, pickBlockToUse(rand), 0, 2);
		world.setBlock(i + 2, j + 6, k + 4, pickBlockToUse(rand), 0, 2);
		world.setBlock(i + 2, j + 6, k + 5, pickBlockToUse(rand), 0, 2);
		world.setBlock(i + 2, j + 6, k + 6, pickBlockToUse(rand), 0, 2);
		world.setBlock(i + 2, j + 6, k + 7, pickBlockToUse(rand), 0, 2);
		world.setBlock(i + 2, j + 6, k + 8, pickBlockToUse(rand), 0, 2);
		world.setBlock(i + 2, j + 7, k + 1, pickBlockToUse(rand), 0, 2);
		world.setBlock(i + 2, j + 7, k + 2, pickBlockToUse(rand), 0, 2);
		world.setBlock(i + 2, j + 7, k + 3, pickBlockToUse(rand), 0, 2);
		world.setBlock(i + 2, j + 7, k + 4, pickBlockToUse(rand), 0, 2);
		world.setBlock(i + 2, j + 7, k + 5, pickBlockToUse(rand), 0, 2);
		world.setBlock(i + 2, j + 7, k + 6, pickBlockToUse(rand), 0, 2);
		world.setBlock(i + 2, j + 7, k + 7, pickBlockToUse(rand), 0, 2);
		world.setBlock(i + 2, j + 7, k + 8, pickBlockToUse(rand), 0, 2);
		world.setBlock(i + 2, j + 8, k + 1, pickBlockToUse(rand), 0, 2);
		world.setBlock(i + 2, j + 8, k + 2, pickBlockToUse(rand), 0, 2);
		world.setBlock(i + 2, j + 8, k + 3, pickBlockToUse(rand), 0, 2);
		world.setBlock(i + 2, j + 8, k + 4, pickBlockToUse(rand), 0, 2);
		world.setBlock(i + 2, j + 8, k + 5, pickBlockToUse(rand), 0, 2);
		world.setBlock(i + 2, j + 8, k + 6, pickBlockToUse(rand), 0, 2);
		world.setBlock(i + 2, j + 8, k + 7, pickBlockToUse(rand), 0, 2);
		world.setBlock(i + 2, j + 8, k + 8, pickBlockToUse(rand), 0, 2);
		world.setBlock(i + 2, j + 9, k + 1, pickBlockToUse(rand), 0, 2);
		world.setBlock(i + 2, j + 9, k + 2, pickBlockToUse(rand), 0, 2);
		world.setBlock(i + 2, j + 9, k + 3, pickBlockToUse(rand), 0, 2);
		world.setBlock(i + 2, j + 9, k + 4, pickBlockToUse(rand), 0, 2);
		world.setBlock(i + 2, j + 9, k + 5, pickBlockToUse(rand), 0, 2);
		world.setBlock(i + 2, j + 9, k + 6, pickBlockToUse(rand), 0, 2);
		world.setBlock(i + 2, j + 9, k + 7, pickBlockToUse(rand), 0, 2);
		world.setBlock(i + 2, j + 9, k + 8, pickBlockToUse(rand), 0, 2);
		world.setBlock(i + 2, j + 10, k + 1, pickBlockToUse(rand), 0, 2);
		world.setBlock(i + 2, j + 10, k + 2, pickBlockToUse(rand), 0, 2);
		world.setBlock(i + 2, j + 10, k + 3, pickBlockToUse(rand), 0, 2);
		world.setBlock(i + 2, j + 10, k + 4, pickBlockToUse(rand), 0, 2);
		world.setBlock(i + 2, j + 10, k + 5, pickBlockToUse(rand), 0, 2);
		world.setBlock(i + 2, j + 10, k + 6, pickBlockToUse(rand), 0, 2);
		world.setBlock(i + 2, j + 10, k + 7, pickBlockToUse(rand), 0, 2);
		world.setBlock(i + 2, j + 10, k + 8, pickBlockToUse(rand), 0, 2);
		world.setBlock(i + 2, j + 11, k + 1, pickBlockToUse(rand), 0, 2);
		world.setBlock(i + 2, j + 11, k + 2, pickBlockToUse(rand), 0, 2);
		world.setBlock(i + 2, j + 11, k + 3, pickBlockToUse(rand), 0, 2);
		world.setBlock(i + 2, j + 11, k + 4, pickBlockToUse(rand), 0, 2);
		world.setBlock(i + 2, j + 11, k + 5, pickBlockToUse(rand), 0, 2);
		world.setBlock(i + 2, j + 11, k + 6, pickBlockToUse(rand), 0, 2);
		world.setBlock(i + 2, j + 11, k + 7, pickBlockToUse(rand), 0, 2);
		world.setBlock(i + 2, j + 11, k + 8, pickBlockToUse(rand), 0, 2);
		world.setBlock(i + 2, j + 12, k + 1, pickBlockToUse(rand), 0, 2);
		world.setBlock(i + 2, j + 12, k + 2, pickBlockToUse(rand), 0, 2);
		world.setBlock(i + 2, j + 12, k + 3, pickBlockToUse(rand), 0, 2);
		world.setBlock(i + 2, j + 12, k + 4, pickBlockToUse(rand), 0, 2);
		world.setBlock(i + 2, j + 12, k + 5, pickBlockToUse(rand), 0, 2);
		world.setBlock(i + 2, j + 12, k + 6, pickBlockToUse(rand), 0, 2);
		world.setBlock(i + 2, j + 12, k + 7, pickBlockToUse(rand), 0, 2);
		world.setBlock(i + 2, j + 12, k + 8, pickBlockToUse(rand), 0, 2);
		world.setBlock(i + 2, j + 13, k + 1, pickBlockToUse(rand), 0, 2);
		world.setBlock(i + 2, j + 13, k + 2, pickBlockToUse(rand), 0, 2);
		world.setBlock(i + 2, j + 13, k + 3, pickBlockToUse(rand), 0, 2);
		world.setBlock(i + 2, j + 13, k + 4, pickBlockToUse(rand), 0, 2);
		world.setBlock(i + 2, j + 13, k + 5, pickBlockToUse(rand), 0, 2);
		world.setBlock(i + 2, j + 13, k + 6, pickBlockToUse(rand), 0, 2);
		world.setBlock(i + 2, j + 13, k + 7, pickBlockToUse(rand), 0, 2);
		world.setBlock(i + 2, j + 13, k + 8, pickBlockToUse(rand), 0, 2);
		world.setBlock(i + 3, j + 0, k + 3, pickBlockToUse(rand), 0, 2);
		world.setBlock(i + 3, j + 0, k + 4, pickBlockToUse(rand), 0, 2);
		world.setBlock(i + 3, j + 0, k + 5, pickBlockToUse(rand), 0, 2);
		world.setBlock(i + 3, j + 0, k + 6, pickBlockToUse(rand), 0, 2);
		world.setBlock(i + 3, j + 1, k + 3, pickBlockToUse(rand), 0, 2);
		world.setBlock(i + 3, j + 1, k + 4, pickBlockToUse(rand), 0, 2);
		world.setBlock(i + 3, j + 1, k + 5, pickBlockToUse(rand), 0, 2);
		world.setBlock(i + 3, j + 1, k + 6, pickBlockToUse(rand), 0, 2);
		world.setBlock(i + 3, j + 2, k + 3, pickBlockToUse(rand), 0, 2);
		world.setBlock(i + 3, j + 2, k + 4, pickBlockToUse(rand), 0, 2);
		world.setBlock(i + 3, j + 2, k + 5, pickBlockToUse(rand), 0, 2);
		world.setBlock(i + 3, j + 2, k + 6, pickBlockToUse(rand), 0, 2);
		world.setBlock(i + 3, j + 3, k + 3, pickBlockToUse(rand), 0, 2);
		world.setBlock(i + 3, j + 3, k + 4, pickBlockToUse(rand), 0, 2);
		world.setBlock(i + 3, j + 3, k + 5, pickBlockToUse(rand), 0, 2);
		world.setBlock(i + 3, j + 3, k + 6, pickBlockToUse(rand), 0, 2);
		world.setBlock(i + 3, j + 4, k + 1, pickBlockToUse(rand), 0, 2);
		world.setBlock(i + 3, j + 4, k + 2, pickBlockToUse(rand), 0, 2);
		world.setBlock(i + 3, j + 4, k + 3, pickBlockToUse(rand), 0, 2);
		world.setBlock(i + 3, j + 4, k + 4, pickBlockToUse(rand), 0, 2);
		world.setBlock(i + 3, j + 4, k + 5, pickBlockToUse(rand), 0, 2);
		world.setBlock(i + 3, j + 4, k + 6, pickBlockToUse(rand), 0, 2);
		world.setBlock(i + 3, j + 4, k + 7, pickBlockToUse(rand), 0, 2);
		world.setBlock(i + 3, j + 4, k + 8, pickBlockToUse(rand), 0, 2);
		world.setBlock(i + 3, j + 5, k + 1, pickBlockToUse(rand), 0, 2);
		world.setBlock(i + 3, j + 5, k + 2, pickBlockToUse(rand), 0, 2);
		world.setBlock(i + 3, j + 5, k + 3, pickBlockToUse(rand), 0, 2);
		world.setBlock(i + 3, j + 5, k + 4, pickBlockToUse(rand), 0, 2);
		world.setBlock(i + 3, j + 5, k + 5, pickBlockToUse(rand), 0, 2);
		world.setBlock(i + 3, j + 5, k + 6, pickBlockToUse(rand), 0, 2);
		world.setBlock(i + 3, j + 5, k + 7, pickBlockToUse(rand), 0, 2);
		world.setBlock(i + 3, j + 5, k + 8, pickBlockToUse(rand), 0, 2);
		world.setBlock(i + 3, j + 6, k + 1, pickBlockToUse(rand), 0, 2);
		world.setBlock(i + 3, j + 6, k + 2, pickBlockToUse(rand), 0, 2);
		world.setBlock(i + 3, j + 6, k + 3, pickBlockToUse(rand), 0, 2);
		world.setBlock(i + 3, j + 6, k + 4, pickBlockToUse(rand), 0, 2);
		world.setBlock(i + 3, j + 6, k + 5, pickBlockToUse(rand), 0, 2);
		world.setBlock(i + 3, j + 6, k + 6, pickBlockToUse(rand), 0, 2);
		world.setBlock(i + 3, j + 6, k + 7, pickBlockToUse(rand), 0, 2);
		world.setBlock(i + 3, j + 6, k + 8, pickBlockToUse(rand), 0, 2);
		world.setBlock(i + 3, j + 7, k + 1, pickBlockToUse(rand), 0, 2);
		world.setBlock(i + 3, j + 7, k + 2, pickBlockToUse(rand), 0, 2);
		world.setBlock(i + 3, j + 7, k + 3, pickBlockToUse(rand), 0, 2);
		world.setBlock(i + 3, j + 7, k + 4, pickBlockToUse(rand), 0, 2);
		world.setBlock(i + 3, j + 7, k + 5, pickBlockToUse(rand), 0, 2);
		world.setBlock(i + 3, j + 7, k + 6, pickBlockToUse(rand), 0, 2);
		world.setBlock(i + 3, j + 7, k + 7, pickBlockToUse(rand), 0, 2);
		world.setBlock(i + 3, j + 7, k + 8, pickBlockToUse(rand), 0, 2);
		world.setBlock(i + 3, j + 8, k + 1, pickBlockToUse(rand), 0, 2);
		world.setBlock(i + 3, j + 8, k + 2, pickBlockToUse(rand), 0, 2);
		world.setBlock(i + 3, j + 8, k + 3, pickBlockToUse(rand), 0, 2);
		world.setBlock(i + 3, j + 8, k + 4, pickBlockToUse(rand), 0, 2);
		world.setBlock(i + 3, j + 8, k + 5, pickBlockToUse(rand), 0, 2);
		world.setBlock(i + 3, j + 8, k + 6, pickBlockToUse(rand), 0, 2);
		world.setBlock(i + 3, j + 8, k + 7, pickBlockToUse(rand), 0, 2);
		world.setBlock(i + 3, j + 8, k + 8, pickBlockToUse(rand), 0, 2);
		world.setBlock(i + 3, j + 9, k + 1, pickBlockToUse(rand), 0, 2);
		world.setBlock(i + 3, j + 9, k + 2, pickBlockToUse(rand), 0, 2);
		world.setBlock(i + 3, j + 9, k + 3, pickBlockToUse(rand), 0, 2);
		world.setBlock(i + 3, j + 9, k + 4, pickBlockToUse(rand), 0, 2);
		world.setBlock(i + 3, j + 9, k + 5, pickBlockToUse(rand), 0, 2);
		world.setBlock(i + 3, j + 9, k + 6, pickBlockToUse(rand), 0, 2);
		world.setBlock(i + 3, j + 9, k + 7, pickBlockToUse(rand), 0, 2);
		world.setBlock(i + 3, j + 9, k + 8, pickBlockToUse(rand), 0, 2);
		world.setBlock(i + 3, j + 10, k + 1, pickBlockToUse(rand), 0, 2);
		world.setBlock(i + 3, j + 10, k + 2, pickBlockToUse(rand), 0, 2);
		world.setBlock(i + 3, j + 10, k + 3, pickBlockToUse(rand), 0, 2);
		world.setBlock(i + 3, j + 10, k + 4, pickBlockToUse(rand), 0, 2);
		world.setBlock(i + 3, j + 10, k + 5, pickBlockToUse(rand), 0, 2);
		world.setBlock(i + 3, j + 10, k + 6, pickBlockToUse(rand), 0, 2);
		world.setBlock(i + 3, j + 10, k + 7, pickBlockToUse(rand), 0, 2);
		world.setBlock(i + 3, j + 10, k + 8, pickBlockToUse(rand), 0, 2);
		world.setBlock(i + 3, j + 11, k + 1, pickBlockToUse(rand), 0, 2);
		world.setBlock(i + 3, j + 11, k + 2, pickBlockToUse(rand), 0, 2);
		world.setBlock(i + 3, j + 11, k + 3, pickBlockToUse(rand), 0, 2);
		world.setBlock(i + 3, j + 11, k + 4, pickBlockToUse(rand), 0, 2);
		world.setBlock(i + 3, j + 11, k + 5, pickBlockToUse(rand), 0, 2);
		world.setBlock(i + 3, j + 11, k + 6, pickBlockToUse(rand), 0, 2);
		world.setBlock(i + 3, j + 11, k + 7, pickBlockToUse(rand), 0, 2);
		world.setBlock(i + 3, j + 11, k + 8, pickBlockToUse(rand), 0, 2);
		world.setBlock(i + 3, j + 12, k + 1, pickBlockToUse(rand), 0, 2);
		world.setBlock(i + 3, j + 12, k + 2, pickBlockToUse(rand), 0, 2);
		world.setBlock(i + 3, j + 12, k + 3, pickBlockToUse(rand), 0, 2);
		world.setBlock(i + 3, j + 12, k + 4, pickBlockToUse(rand), 0, 2);
		world.setBlock(i + 3, j + 12, k + 5, pickBlockToUse(rand), 0, 2);
		world.setBlock(i + 3, j + 12, k + 6, pickBlockToUse(rand), 0, 2);
		world.setBlock(i + 3, j + 12, k + 7, pickBlockToUse(rand), 0, 2);
		world.setBlock(i + 3, j + 12, k + 8, pickBlockToUse(rand), 0, 2);
		world.setBlock(i + 3, j + 13, k + 1, pickBlockToUse(rand), 0, 2);
		world.setBlock(i + 3, j + 13, k + 2, pickBlockToUse(rand), 0, 2);
		world.setBlock(i + 3, j + 13, k + 3, pickBlockToUse(rand), 0, 2);
		world.setBlock(i + 3, j + 13, k + 4, pickBlockToUse(rand), 0, 2);
		world.setBlock(i + 3, j + 13, k + 5, pickBlockToUse(rand), 0, 2);
		world.setBlock(i + 3, j + 13, k + 6, pickBlockToUse(rand), 0, 2);
		world.setBlock(i + 3, j + 13, k + 7, pickBlockToUse(rand), 0, 2);
		world.setBlock(i + 3, j + 13, k + 8, pickBlockToUse(rand), 0, 2);
		world.setBlock(i + 4, j + 0, k + 3, pickBlockToUse(rand), 0, 2);
		world.setBlock(i + 4, j + 0, k + 4, pickBlockToUse(rand), 0, 2);
		world.setBlock(i + 4, j + 0, k + 5, pickBlockToUse(rand), 0, 2);
		world.setBlock(i + 4, j + 0, k + 6, pickBlockToUse(rand), 0, 2);
		world.setBlock(i + 4, j + 1, k + 3, pickBlockToUse(rand), 0, 2);
		world.setBlock(i + 4, j + 1, k + 4, pickBlockToUse(rand), 0, 2);
		world.setBlock(i + 4, j + 1, k + 5, pickBlockToUse(rand), 0, 2);
		world.setBlock(i + 4, j + 1, k + 6, pickBlockToUse(rand), 0, 2);
		world.setBlock(i + 4, j + 2, k + 3, pickBlockToUse(rand), 0, 2);
		world.setBlock(i + 4, j + 2, k + 4, pickBlockToUse(rand), 0, 2);
		world.setBlock(i + 4, j + 2, k + 5, pickBlockToUse(rand), 0, 2);
		world.setBlock(i + 4, j + 2, k + 6, pickBlockToUse(rand), 0, 2);
		world.setBlock(i + 4, j + 3, k + 3, pickBlockToUse(rand), 0, 2);
		world.setBlock(i + 4, j + 3, k + 4, pickBlockToUse(rand), 0, 2);
		world.setBlock(i + 4, j + 3, k + 5, pickBlockToUse(rand), 0, 2);
		world.setBlock(i + 4, j + 3, k + 6, pickBlockToUse(rand), 0, 2);
		world.setBlock(i + 4, j + 4, k + 1, pickBlockToUse(rand), 0, 2);
		world.setBlock(i + 4, j + 4, k + 2, pickBlockToUse(rand), 0, 2);
		world.setBlock(i + 4, j + 4, k + 3, pickBlockToUse(rand), 0, 2);
		world.setBlock(i + 4, j + 4, k + 4, pickBlockToUse(rand), 0, 2);
		world.setBlock(i + 4, j + 4, k + 5, pickBlockToUse(rand), 0, 2);
		world.setBlock(i + 4, j + 4, k + 6, pickBlockToUse(rand), 0, 2);
		world.setBlock(i + 4, j + 4, k + 7, pickBlockToUse(rand), 0, 2);
		world.setBlock(i + 4, j + 4, k + 8, pickBlockToUse(rand), 0, 2);
		world.setBlock(i + 4, j + 5, k + 1, pickBlockToUse(rand), 0, 2);
		world.setBlock(i + 4, j + 5, k + 2, pickBlockToUse(rand), 0, 2);
		world.setBlock(i + 4, j + 5, k + 3, pickBlockToUse(rand), 0, 2);
		world.setBlock(i + 4, j + 5, k + 4, pickBlockToUse(rand), 0, 2);
		world.setBlock(i + 4, j + 5, k + 5, pickBlockToUse(rand), 0, 2);
		world.setBlock(i + 4, j + 5, k + 6, pickBlockToUse(rand), 0, 2);
		world.setBlock(i + 4, j + 5, k + 7, pickBlockToUse(rand), 0, 2);
		world.setBlock(i + 4, j + 5, k + 8, pickBlockToUse(rand), 0, 2);
		world.setBlock(i + 4, j + 6, k + 1, pickBlockToUse(rand), 0, 2);
		world.setBlock(i + 4, j + 6, k + 2, pickBlockToUse(rand), 0, 2);
		world.setBlock(i + 4, j + 6, k + 3, pickBlockToUse(rand), 0, 2);
		world.setBlock(i + 4, j + 6, k + 4, pickBlockToUse(rand), 0, 2);
		world.setBlock(i + 4, j + 6, k + 5, pickBlockToUse(rand), 0, 2);
		world.setBlock(i + 4, j + 6, k + 6, pickBlockToUse(rand), 0, 2);
		world.setBlock(i + 4, j + 6, k + 7, pickBlockToUse(rand), 0, 2);
		world.setBlock(i + 4, j + 6, k + 8, pickBlockToUse(rand), 0, 2);
		world.setBlock(i + 4, j + 7, k + 1, pickBlockToUse(rand), 0, 2);
		world.setBlock(i + 4, j + 7, k + 2, pickBlockToUse(rand), 0, 2);
		world.setBlock(i + 4, j + 7, k + 3, pickBlockToUse(rand), 0, 2);
		world.setBlock(i + 4, j + 7, k + 4, pickBlockToUse(rand), 0, 2);
		world.setBlock(i + 4, j + 7, k + 5, pickBlockToUse(rand), 0, 2);
		world.setBlock(i + 4, j + 7, k + 6, pickBlockToUse(rand), 0, 2);
		world.setBlock(i + 4, j + 7, k + 7, pickBlockToUse(rand), 0, 2);
		world.setBlock(i + 4, j + 7, k + 8, pickBlockToUse(rand), 0, 2);
		world.setBlock(i + 4, j + 8, k + 1, pickBlockToUse(rand), 0, 2);
		world.setBlock(i + 4, j + 8, k + 2, pickBlockToUse(rand), 0, 2);
		world.setBlock(i + 4, j + 8, k + 3, pickBlockToUse(rand), 0, 2);
		world.setBlock(i + 4, j + 8, k + 4, pickBlockToUse(rand), 0, 2);
		world.setBlock(i + 4, j + 8, k + 5, pickBlockToUse(rand), 0, 2);
		world.setBlock(i + 4, j + 8, k + 6, pickBlockToUse(rand), 0, 2);
		world.setBlock(i + 4, j + 8, k + 7, pickBlockToUse(rand), 0, 2);
		world.setBlock(i + 4, j + 8, k + 8, pickBlockToUse(rand), 0, 2);
		world.setBlock(i + 4, j + 9, k + 1, pickBlockToUse(rand), 0, 2);
		world.setBlock(i + 4, j + 9, k + 2, pickBlockToUse(rand), 0, 2);
		world.setBlock(i + 4, j + 9, k + 3, pickBlockToUse(rand), 0, 2);
		world.setBlock(i + 4, j + 9, k + 4, pickBlockToUse(rand), 0, 2);
		world.setBlock(i + 4, j + 9, k + 5, pickBlockToUse(rand), 0, 2);
		world.setBlock(i + 4, j + 9, k + 6, pickBlockToUse(rand), 0, 2);
		world.setBlock(i + 4, j + 9, k + 7, pickBlockToUse(rand), 0, 2);
		world.setBlock(i + 4, j + 9, k + 8, pickBlockToUse(rand), 0, 2);
		world.setBlock(i + 4, j + 10, k + 1, pickBlockToUse(rand), 0, 2);
		world.setBlock(i + 4, j + 10, k + 2, pickBlockToUse(rand), 0, 2);
		world.setBlock(i + 4, j + 10, k + 3, pickBlockToUse(rand), 0, 2);
		world.setBlock(i + 4, j + 10, k + 4, pickBlockToUse(rand), 0, 2);
		world.setBlock(i + 4, j + 10, k + 5, pickBlockToUse(rand), 0, 2);
		world.setBlock(i + 4, j + 10, k + 6, pickBlockToUse(rand), 0, 2);
		world.setBlock(i + 4, j + 10, k + 7, pickBlockToUse(rand), 0, 2);
		world.setBlock(i + 4, j + 10, k + 8, pickBlockToUse(rand), 0, 2);
		world.setBlock(i + 4, j + 11, k + 1, pickBlockToUse(rand), 0, 2);
		world.setBlock(i + 4, j + 11, k + 2, pickBlockToUse(rand), 0, 2);
		world.setBlock(i + 4, j + 11, k + 3, pickBlockToUse(rand), 0, 2);
		world.setBlock(i + 4, j + 11, k + 4, pickBlockToUse(rand), 0, 2);
		world.setBlock(i + 4, j + 11, k + 5, pickBlockToUse(rand), 0, 2);
		world.setBlock(i + 4, j + 11, k + 6, pickBlockToUse(rand), 0, 2);
		world.setBlock(i + 4, j + 11, k + 7, pickBlockToUse(rand), 0, 2);
		world.setBlock(i + 4, j + 11, k + 8, pickBlockToUse(rand), 0, 2);
		world.setBlock(i + 4, j + 12, k + 1, pickBlockToUse(rand), 0, 2);
		world.setBlock(i + 4, j + 12, k + 2, pickBlockToUse(rand), 0, 2);
		world.setBlock(i + 4, j + 12, k + 3, pickBlockToUse(rand), 0, 2);
		world.setBlock(i + 4, j + 12, k + 4, pickBlockToUse(rand), 0, 2);
		world.setBlock(i + 4, j + 12, k + 5, pickBlockToUse(rand), 0, 2);
		world.setBlock(i + 4, j + 12, k + 6, pickBlockToUse(rand), 0, 2);
		world.setBlock(i + 4, j + 12, k + 7, pickBlockToUse(rand), 0, 2);
		world.setBlock(i + 4, j + 12, k + 8, pickBlockToUse(rand), 0, 2);
		world.setBlock(i + 4, j + 13, k + 1, pickBlockToUse(rand), 0, 2);
		world.setBlock(i + 4, j + 13, k + 2, pickBlockToUse(rand), 0, 2);
		world.setBlock(i + 4, j + 13, k + 3, pickBlockToUse(rand), 0, 2);
		world.setBlock(i + 4, j + 13, k + 4, pickBlockToUse(rand), 0, 2);
		world.setBlock(i + 4, j + 13, k + 5, pickBlockToUse(rand), 0, 2);
		world.setBlock(i + 4, j + 13, k + 6, pickBlockToUse(rand), 0, 2);
		world.setBlock(i + 4, j + 13, k + 7, pickBlockToUse(rand), 0, 2);
		world.setBlock(i + 4, j + 13, k + 8, pickBlockToUse(rand), 0, 2);
		world.setBlock(i + 5, j + 0, k + 3, pickBlockToUse(rand), 0, 2);
		world.setBlock(i + 5, j + 0, k + 4, pickBlockToUse(rand), 0, 2);
		world.setBlock(i + 5, j + 0, k + 5, pickBlockToUse(rand), 0, 2);
		world.setBlock(i + 5, j + 0, k + 6, pickBlockToUse(rand), 0, 2);
		world.setBlock(i + 5, j + 1, k + 3, pickBlockToUse(rand), 0, 2);
		world.setBlock(i + 5, j + 1, k + 4, pickBlockToUse(rand), 0, 2);
		world.setBlock(i + 5, j + 1, k + 5, pickBlockToUse(rand), 0, 2);
		world.setBlock(i + 5, j + 1, k + 6, pickBlockToUse(rand), 0, 2);
		world.setBlock(i + 5, j + 2, k + 3, pickBlockToUse(rand), 0, 2);
		world.setBlock(i + 5, j + 2, k + 4, pickBlockToUse(rand), 0, 2);
		world.setBlock(i + 5, j + 2, k + 5, pickBlockToUse(rand), 0, 2);
		world.setBlock(i + 5, j + 2, k + 6, pickBlockToUse(rand), 0, 2);
		world.setBlock(i + 5, j + 3, k + 3, pickBlockToUse(rand), 0, 2);
		world.setBlock(i + 5, j + 3, k + 4, pickBlockToUse(rand), 0, 2);
		world.setBlock(i + 5, j + 3, k + 5, pickBlockToUse(rand), 0, 2);
		world.setBlock(i + 5, j + 3, k + 6, pickBlockToUse(rand), 0, 2);
		world.setBlock(i + 5, j + 4, k + 1, pickBlockToUse(rand), 0, 2);
		world.setBlock(i + 5, j + 4, k + 2, pickBlockToUse(rand), 0, 2);
		world.setBlock(i + 5, j + 4, k + 3, pickBlockToUse(rand), 0, 2);
		world.setBlock(i + 5, j + 4, k + 4, pickBlockToUse(rand), 0, 2);
		world.setBlock(i + 5, j + 4, k + 5, pickBlockToUse(rand), 0, 2);
		world.setBlock(i + 5, j + 4, k + 6, pickBlockToUse(rand), 0, 2);
		world.setBlock(i + 5, j + 4, k + 7, pickBlockToUse(rand), 0, 2);
		world.setBlock(i + 5, j + 4, k + 8, pickBlockToUse(rand), 0, 2);
		world.setBlock(i + 5, j + 5, k + 1, pickBlockToUse(rand), 0, 2);
		world.setBlock(i + 5, j + 5, k + 2, pickBlockToUse(rand), 0, 2);
		world.setBlock(i + 5, j + 5, k + 3, pickBlockToUse(rand), 0, 2);
		world.setBlock(i + 5, j + 5, k + 4, pickBlockToUse(rand), 0, 2);
		world.setBlock(i + 5, j + 5, k + 5, pickBlockToUse(rand), 0, 2);
		world.setBlock(i + 5, j + 5, k + 6, pickBlockToUse(rand), 0, 2);
		world.setBlock(i + 5, j + 5, k + 7, pickBlockToUse(rand), 0, 2);
		world.setBlock(i + 5, j + 5, k + 8, pickBlockToUse(rand), 0, 2);
		world.setBlock(i + 5, j + 6, k + 1, pickBlockToUse(rand), 0, 2);
		world.setBlock(i + 5, j + 6, k + 2, pickBlockToUse(rand), 0, 2);
		world.setBlock(i + 5, j + 6, k + 3, pickBlockToUse(rand), 0, 2);
		world.setBlock(i + 5, j + 6, k + 4, pickBlockToUse(rand), 0, 2);
		world.setBlock(i + 5, j + 6, k + 5, pickBlockToUse(rand), 0, 2);
		world.setBlock(i + 5, j + 6, k + 6, pickBlockToUse(rand), 0, 2);
		world.setBlock(i + 5, j + 6, k + 7, pickBlockToUse(rand), 0, 2);
		world.setBlock(i + 5, j + 6, k + 8, pickBlockToUse(rand), 0, 2);
		world.setBlock(i + 5, j + 7, k + 1, pickBlockToUse(rand), 0, 2);
		world.setBlock(i + 5, j + 7, k + 2, pickBlockToUse(rand), 0, 2);
		world.setBlock(i + 5, j + 7, k + 3, pickBlockToUse(rand), 0, 2);
		world.setBlock(i + 5, j + 7, k + 4, pickBlockToUse(rand), 0, 2);
		world.setBlock(i + 5, j + 7, k + 5, pickBlockToUse(rand), 0, 2);
		world.setBlock(i + 5, j + 7, k + 6, pickBlockToUse(rand), 0, 2);
		world.setBlock(i + 5, j + 7, k + 7, pickBlockToUse(rand), 0, 2);
		world.setBlock(i + 5, j + 7, k + 8, pickBlockToUse(rand), 0, 2);
		world.setBlock(i + 5, j + 8, k + 1, pickBlockToUse(rand), 0, 2);
		world.setBlock(i + 5, j + 8, k + 2, pickBlockToUse(rand), 0, 2);
		world.setBlock(i + 5, j + 8, k + 3, pickBlockToUse(rand), 0, 2);
		world.setBlock(i + 5, j + 8, k + 4, pickBlockToUse(rand), 0, 2);
		world.setBlock(i + 5, j + 8, k + 5, pickBlockToUse(rand), 0, 2);
		world.setBlock(i + 5, j + 8, k + 6, pickBlockToUse(rand), 0, 2);
		world.setBlock(i + 5, j + 8, k + 7, pickBlockToUse(rand), 0, 2);
		world.setBlock(i + 5, j + 8, k + 8, pickBlockToUse(rand), 0, 2);
		world.setBlock(i + 5, j + 9, k + 1, pickBlockToUse(rand), 0, 2);
		world.setBlock(i + 5, j + 9, k + 2, pickBlockToUse(rand), 0, 2);
		world.setBlock(i + 5, j + 9, k + 3, pickBlockToUse(rand), 0, 2);
		world.setBlock(i + 5, j + 9, k + 4, pickBlockToUse(rand), 0, 2);
		world.setBlock(i + 5, j + 9, k + 5, pickBlockToUse(rand), 0, 2);
		world.setBlock(i + 5, j + 9, k + 6, pickBlockToUse(rand), 0, 2);
		world.setBlock(i + 5, j + 9, k + 7, pickBlockToUse(rand), 0, 2);
		world.setBlock(i + 5, j + 9, k + 8, pickBlockToUse(rand), 0, 2);
		world.setBlock(i + 5, j + 10, k + 1, pickBlockToUse(rand), 0, 2);
		world.setBlock(i + 5, j + 10, k + 2, pickBlockToUse(rand), 0, 2);
		world.setBlock(i + 5, j + 10, k + 3, pickBlockToUse(rand), 0, 2);
		world.setBlock(i + 5, j + 10, k + 4, pickBlockToUse(rand), 0, 2);
		world.setBlock(i + 5, j + 10, k + 5, pickBlockToUse(rand), 0, 2);
		world.setBlock(i + 5, j + 10, k + 6, pickBlockToUse(rand), 0, 2);
		world.setBlock(i + 5, j + 10, k + 7, pickBlockToUse(rand), 0, 2);
		world.setBlock(i + 5, j + 10, k + 8, pickBlockToUse(rand), 0, 2);
		world.setBlock(i + 5, j + 11, k + 1, pickBlockToUse(rand), 0, 2);
		world.setBlock(i + 5, j + 11, k + 2, pickBlockToUse(rand), 0, 2);
		world.setBlock(i + 5, j + 11, k + 3, pickBlockToUse(rand), 0, 2);
		world.setBlock(i + 5, j + 11, k + 4, pickBlockToUse(rand), 0, 2);
		world.setBlock(i + 5, j + 11, k + 5, pickBlockToUse(rand), 0, 2);
		world.setBlock(i + 5, j + 11, k + 6, pickBlockToUse(rand), 0, 2);
		world.setBlock(i + 5, j + 11, k + 7, pickBlockToUse(rand), 0, 2);
		world.setBlock(i + 5, j + 11, k + 8, pickBlockToUse(rand), 0, 2);
		world.setBlock(i + 5, j + 12, k + 1, pickBlockToUse(rand), 0, 2);
		world.setBlock(i + 5, j + 12, k + 2, pickBlockToUse(rand), 0, 2);
		world.setBlock(i + 5, j + 12, k + 3, pickBlockToUse(rand), 0, 2);
		world.setBlock(i + 5, j + 12, k + 4, pickBlockToUse(rand), 0, 2);
		world.setBlock(i + 5, j + 12, k + 5, pickBlockToUse(rand), 0, 2);
		world.setBlock(i + 5, j + 12, k + 6, pickBlockToUse(rand), 0, 2);
		world.setBlock(i + 5, j + 12, k + 7, pickBlockToUse(rand), 0, 2);
		world.setBlock(i + 5, j + 12, k + 8, pickBlockToUse(rand), 0, 2);
		world.setBlock(i + 5, j + 13, k + 1, pickBlockToUse(rand), 0, 2);
		world.setBlock(i + 5, j + 13, k + 2, pickBlockToUse(rand), 0, 2);
		world.setBlock(i + 5, j + 13, k + 3, pickBlockToUse(rand), 0, 2);
		world.setBlock(i + 5, j + 13, k + 4, pickBlockToUse(rand), 0, 2);
		world.setBlock(i + 5, j + 13, k + 5, pickBlockToUse(rand), 0, 2);
		world.setBlock(i + 5, j + 13, k + 6, pickBlockToUse(rand), 0, 2);
		world.setBlock(i + 5, j + 13, k + 7, pickBlockToUse(rand), 0, 2);
		world.setBlock(i + 5, j + 13, k + 8, pickBlockToUse(rand), 0, 2);
		world.setBlock(i + 6, j + 0, k + 3, pickBlockToUse(rand), 0, 2);
		world.setBlock(i + 6, j + 0, k + 4, pickBlockToUse(rand), 0, 2);
		world.setBlock(i + 6, j + 0, k + 5, pickBlockToUse(rand), 0, 2);
		world.setBlock(i + 6, j + 0, k + 6, pickBlockToUse(rand), 0, 2);
		world.setBlock(i + 6, j + 1, k + 3, pickBlockToUse(rand), 0, 2);
		world.setBlock(i + 6, j + 1, k + 4, pickBlockToUse(rand), 0, 2);
		world.setBlock(i + 6, j + 1, k + 5, pickBlockToUse(rand), 0, 2);
		world.setBlock(i + 6, j + 1, k + 6, pickBlockToUse(rand), 0, 2);
		world.setBlock(i + 6, j + 2, k + 3, pickBlockToUse(rand), 0, 2);
		world.setBlock(i + 6, j + 2, k + 4, pickBlockToUse(rand), 0, 2);
		world.setBlock(i + 6, j + 2, k + 5, pickBlockToUse(rand), 0, 2);
		world.setBlock(i + 6, j + 2, k + 6, pickBlockToUse(rand), 0, 2);
		world.setBlock(i + 6, j + 3, k + 3, pickBlockToUse(rand), 0, 2);
		world.setBlock(i + 6, j + 3, k + 4, pickBlockToUse(rand), 0, 2);
		world.setBlock(i + 6, j + 3, k + 5, pickBlockToUse(rand), 0, 2);
		world.setBlock(i + 6, j + 3, k + 6, pickBlockToUse(rand), 0, 2);
		world.setBlock(i + 6, j + 4, k + 1, pickBlockToUse(rand), 0, 2);
		world.setBlock(i + 6, j + 4, k + 2, pickBlockToUse(rand), 0, 2);
		world.setBlock(i + 6, j + 4, k + 3, pickBlockToUse(rand), 0, 2);
		world.setBlock(i + 6, j + 4, k + 4, pickBlockToUse(rand), 0, 2);
		world.setBlock(i + 6, j + 4, k + 5, pickBlockToUse(rand), 0, 2);
		world.setBlock(i + 6, j + 4, k + 6, pickBlockToUse(rand), 0, 2);
		world.setBlock(i + 6, j + 4, k + 7, pickBlockToUse(rand), 0, 2);
		world.setBlock(i + 6, j + 4, k + 8, pickBlockToUse(rand), 0, 2);
		world.setBlock(i + 6, j + 5, k + 1, pickBlockToUse(rand), 0, 2);
		world.setBlock(i + 6, j + 5, k + 2, pickBlockToUse(rand), 0, 2);
		world.setBlock(i + 6, j + 5, k + 3, pickBlockToUse(rand), 0, 2);
		world.setBlock(i + 6, j + 5, k + 4, pickBlockToUse(rand), 0, 2);
		world.setBlock(i + 6, j + 5, k + 5, pickBlockToUse(rand), 0, 2);
		world.setBlock(i + 6, j + 5, k + 6, pickBlockToUse(rand), 0, 2);
		world.setBlock(i + 6, j + 5, k + 7, pickBlockToUse(rand), 0, 2);
		world.setBlock(i + 6, j + 5, k + 8, pickBlockToUse(rand), 0, 2);
		world.setBlock(i + 6, j + 6, k + 1, pickBlockToUse(rand), 0, 2);
		world.setBlock(i + 6, j + 6, k + 2, pickBlockToUse(rand), 0, 2);
		world.setBlock(i + 6, j + 6, k + 3, pickBlockToUse(rand), 0, 2);
		world.setBlock(i + 6, j + 6, k + 4, pickBlockToUse(rand), 0, 2);
		world.setBlock(i + 6, j + 6, k + 5, pickBlockToUse(rand), 0, 2);
		world.setBlock(i + 6, j + 6, k + 6, pickBlockToUse(rand), 0, 2);
		world.setBlock(i + 6, j + 6, k + 7, pickBlockToUse(rand), 0, 2);
		world.setBlock(i + 6, j + 6, k + 8, pickBlockToUse(rand), 0, 2);
		world.setBlock(i + 6, j + 7, k + 1, pickBlockToUse(rand), 0, 2);
		world.setBlock(i + 6, j + 7, k + 2, pickBlockToUse(rand), 0, 2);
		world.setBlock(i + 6, j + 7, k + 3, pickBlockToUse(rand), 0, 2);
		world.setBlock(i + 6, j + 7, k + 4, pickBlockToUse(rand), 0, 2);
		world.setBlock(i + 6, j + 7, k + 5, pickBlockToUse(rand), 0, 2);
		world.setBlock(i + 6, j + 7, k + 6, pickBlockToUse(rand), 0, 2);
		world.setBlock(i + 6, j + 7, k + 7, pickBlockToUse(rand), 0, 2);
		world.setBlock(i + 6, j + 7, k + 8, pickBlockToUse(rand), 0, 2);
		world.setBlock(i + 6, j + 8, k + 1, pickBlockToUse(rand), 0, 2);
		world.setBlock(i + 6, j + 8, k + 2, pickBlockToUse(rand), 0, 2);
		world.setBlock(i + 6, j + 8, k + 3, pickBlockToUse(rand), 0, 2);
		world.setBlock(i + 6, j + 8, k + 4, pickBlockToUse(rand), 0, 2);
		world.setBlock(i + 6, j + 8, k + 5, pickBlockToUse(rand), 0, 2);
		world.setBlock(i + 6, j + 8, k + 7, pickBlockToUse(rand), 0, 2);
		world.setBlock(i + 6, j + 8, k + 8, pickBlockToUse(rand), 0, 2);
		world.setBlock(i + 6, j + 9, k + 1, pickBlockToUse(rand), 0, 2);
		world.setBlock(i + 6, j + 9, k + 2, pickBlockToUse(rand), 0, 2);
		world.setBlock(i + 6, j + 9, k + 3, pickBlockToUse(rand), 0, 2);
		world.setBlock(i + 6, j + 9, k + 4, pickBlockToUse(rand), 0, 2);
		world.setBlock(i + 6, j + 9, k + 5, pickBlockToUse(rand), 0, 2);
		world.setBlock(i + 6, j + 9, k + 6, pickBlockToUse(rand), 0, 2);
		world.setBlock(i + 6, j + 9, k + 7, pickBlockToUse(rand), 0, 2);
		world.setBlock(i + 6, j + 9, k + 8, pickBlockToUse(rand), 0, 2);
		world.setBlock(i + 6, j + 10, k + 1, pickBlockToUse(rand), 0, 2);
		world.setBlock(i + 6, j + 10, k + 2, pickBlockToUse(rand), 0, 2);
		world.setBlock(i + 6, j + 10, k + 3, pickBlockToUse(rand), 0, 2);
		world.setBlock(i + 6, j + 10, k + 4, pickBlockToUse(rand), 0, 2);
		world.setBlock(i + 6, j + 10, k + 5, pickBlockToUse(rand), 0, 2);
		world.setBlock(i + 6, j + 10, k + 6, pickBlockToUse(rand), 0, 2);
		world.setBlock(i + 6, j + 10, k + 7, pickBlockToUse(rand), 0, 2);
		world.setBlock(i + 6, j + 10, k + 8, pickBlockToUse(rand), 0, 2);
		world.setBlock(i + 6, j + 11, k + 1, pickBlockToUse(rand), 0, 2);
		world.setBlock(i + 6, j + 11, k + 2, pickBlockToUse(rand), 0, 2);
		world.setBlock(i + 6, j + 11, k + 3, pickBlockToUse(rand), 0, 2);
		world.setBlock(i + 6, j + 11, k + 4, pickBlockToUse(rand), 0, 2);
		world.setBlock(i + 6, j + 11, k + 5, pickBlockToUse(rand), 0, 2);
		world.setBlock(i + 6, j + 11, k + 6, pickBlockToUse(rand), 0, 2);
		world.setBlock(i + 6, j + 11, k + 7, pickBlockToUse(rand), 0, 2);
		world.setBlock(i + 6, j + 11, k + 8, pickBlockToUse(rand), 0, 2);
		world.setBlock(i + 6, j + 12, k + 1, pickBlockToUse(rand), 0, 2);
		world.setBlock(i + 6, j + 12, k + 2, pickBlockToUse(rand), 0, 2);
		world.setBlock(i + 6, j + 12, k + 3, pickBlockToUse(rand), 0, 2);
		world.setBlock(i + 6, j + 12, k + 4, pickBlockToUse(rand), 0, 2);
		world.setBlock(i + 6, j + 12, k + 5, pickBlockToUse(rand), 0, 2);
		world.setBlock(i + 6, j + 12, k + 6, pickBlockToUse(rand), 0, 2);
		world.setBlock(i + 6, j + 12, k + 7, pickBlockToUse(rand), 0, 2);
		world.setBlock(i + 6, j + 12, k + 8, pickBlockToUse(rand), 0, 2);
		world.setBlock(i + 6, j + 13, k + 1, pickBlockToUse(rand), 0, 2);
		world.setBlock(i + 6, j + 13, k + 2, pickBlockToUse(rand), 0, 2);
		world.setBlock(i + 6, j + 13, k + 3, pickBlockToUse(rand), 0, 2);
		world.setBlock(i + 6, j + 13, k + 4, pickBlockToUse(rand), 0, 2);
		world.setBlock(i + 6, j + 13, k + 5, pickBlockToUse(rand), 0, 2);
		world.setBlock(i + 6, j + 13, k + 6, pickBlockToUse(rand), 0, 2);
		world.setBlock(i + 6, j + 13, k + 7, pickBlockToUse(rand), 0, 2);
		world.setBlock(i + 6, j + 13, k + 8, pickBlockToUse(rand), 0, 2);
		world.setBlock(i + 7, j + 4, k + 1, pickBlockToUse(rand), 0, 2);
		world.setBlock(i + 7, j + 4, k + 2, pickBlockToUse(rand), 0, 2);
		world.setBlock(i + 7, j + 4, k + 3, pickBlockToUse(rand), 0, 2);
		world.setBlock(i + 7, j + 4, k + 4, pickBlockToUse(rand), 0, 2);
		world.setBlock(i + 7, j + 4, k + 5, pickBlockToUse(rand), 0, 2);
		world.setBlock(i + 7, j + 4, k + 6, pickBlockToUse(rand), 0, 2);
		world.setBlock(i + 7, j + 4, k + 7, pickBlockToUse(rand), 0, 2);
		world.setBlock(i + 7, j + 4, k + 8, pickBlockToUse(rand), 0, 2);
		world.setBlock(i + 7, j + 5, k + 1, pickBlockToUse(rand), 0, 2);
		world.setBlock(i + 7, j + 5, k + 2, pickBlockToUse(rand), 0, 2);
		world.setBlock(i + 7, j + 5, k + 3, pickBlockToUse(rand), 0, 2);
		world.setBlock(i + 7, j + 5, k + 4, pickBlockToUse(rand), 0, 2);
		world.setBlock(i + 7, j + 5, k + 5, pickBlockToUse(rand), 0, 2);
		world.setBlock(i + 7, j + 5, k + 6, pickBlockToUse(rand), 0, 2);
		world.setBlock(i + 7, j + 5, k + 7, pickBlockToUse(rand), 0, 2);
		world.setBlock(i + 7, j + 5, k + 8, pickBlockToUse(rand), 0, 2);
		world.setBlock(i + 7, j + 6, k + 1, pickBlockToUse(rand), 0, 2);
		world.setBlock(i + 7, j + 6, k + 2, pickBlockToUse(rand), 0, 2);
		world.setBlock(i + 7, j + 6, k + 3, pickBlockToUse(rand), 0, 2);
		world.setBlock(i + 7, j + 6, k + 4, pickBlockToUse(rand), 0, 2);
		world.setBlock(i + 7, j + 6, k + 5, pickBlockToUse(rand), 0, 2);
		world.setBlock(i + 7, j + 6, k + 6, pickBlockToUse(rand), 0, 2);
		world.setBlock(i + 7, j + 6, k + 7, pickBlockToUse(rand), 0, 2);
		world.setBlock(i + 7, j + 6, k + 8, pickBlockToUse(rand), 0, 2);
		world.setBlock(i + 7, j + 7, k + 1, pickBlockToUse(rand), 0, 2);
		world.setBlock(i + 7, j + 7, k + 2, pickBlockToUse(rand), 0, 2);
		world.setBlock(i + 7, j + 7, k + 3, pickBlockToUse(rand), 0, 2);
		world.setBlock(i + 7, j + 7, k + 4, pickBlockToUse(rand), 0, 2);
		world.setBlock(i + 7, j + 7, k + 5, pickBlockToUse(rand), 0, 2);
		world.setBlock(i + 7, j + 7, k + 6, pickBlockToUse(rand), 0, 2);
		world.setBlock(i + 7, j + 7, k + 7, pickBlockToUse(rand), 0, 2);
		world.setBlock(i + 7, j + 7, k + 8, pickBlockToUse(rand), 0, 2);
		world.setBlock(i + 7, j + 8, k + 1, pickBlockToUse(rand), 0, 2);
		world.setBlock(i + 7, j + 8, k + 2, pickBlockToUse(rand), 0, 2);
		world.setBlock(i + 7, j + 8, k + 3, pickBlockToUse(rand), 0, 2);
		world.setBlock(i + 7, j + 8, k + 4, pickBlockToUse(rand), 0, 2);
		world.setBlock(i + 7, j + 8, k + 5, pickBlockToUse(rand), 0, 2);
		world.setBlock(i + 7, j + 8, k + 6, pickBlockToUse(rand), 0, 2);
		world.setBlock(i + 7, j + 8, k + 7, pickBlockToUse(rand), 0, 2);
		world.setBlock(i + 7, j + 8, k + 8, pickBlockToUse(rand), 0, 2);
		world.setBlock(i + 7, j + 9, k + 1, pickBlockToUse(rand), 0, 2);
		world.setBlock(i + 7, j + 9, k + 2, pickBlockToUse(rand), 0, 2);
		world.setBlock(i + 7, j + 9, k + 3, pickBlockToUse(rand), 0, 2);
		world.setBlock(i + 7, j + 9, k + 4, pickBlockToUse(rand), 0, 2);
		world.setBlock(i + 7, j + 9, k + 5, pickBlockToUse(rand), 0, 2);
		world.setBlock(i + 7, j + 9, k + 6, pickBlockToUse(rand), 0, 2);
		world.setBlock(i + 7, j + 9, k + 7, pickBlockToUse(rand), 0, 2);
		world.setBlock(i + 7, j + 9, k + 8, pickBlockToUse(rand), 0, 2);
		world.setBlock(i + 7, j + 10, k + 1, pickBlockToUse(rand), 0, 2);
		world.setBlock(i + 7, j + 10, k + 2, pickBlockToUse(rand), 0, 2);
		world.setBlock(i + 7, j + 10, k + 3, pickBlockToUse(rand), 0, 2);
		world.setBlock(i + 7, j + 10, k + 4, pickBlockToUse(rand), 0, 2);
		world.setBlock(i + 7, j + 10, k + 5, pickBlockToUse(rand), 0, 2);
		world.setBlock(i + 7, j + 10, k + 6, pickBlockToUse(rand), 0, 2);
		world.setBlock(i + 7, j + 10, k + 7, pickBlockToUse(rand), 0, 2);
		world.setBlock(i + 7, j + 10, k + 8, pickBlockToUse(rand), 0, 2);
		world.setBlock(i + 7, j + 11, k + 1, pickBlockToUse(rand), 0, 2);
		world.setBlock(i + 7, j + 11, k + 2, pickBlockToUse(rand), 0, 2);
		world.setBlock(i + 7, j + 11, k + 3, pickBlockToUse(rand), 0, 2);
		world.setBlock(i + 7, j + 11, k + 4, pickBlockToUse(rand), 0, 2);
		world.setBlock(i + 7, j + 11, k + 5, pickBlockToUse(rand), 0, 2);
		world.setBlock(i + 7, j + 11, k + 6, pickBlockToUse(rand), 0, 2);
		world.setBlock(i + 7, j + 11, k + 7, pickBlockToUse(rand), 0, 2);
		world.setBlock(i + 7, j + 11, k + 8, pickBlockToUse(rand), 0, 2);
		world.setBlock(i + 7, j + 12, k + 1, pickBlockToUse(rand), 0, 2);
		world.setBlock(i + 7, j + 12, k + 2, pickBlockToUse(rand), 0, 2);
		world.setBlock(i + 7, j + 12, k + 3, pickBlockToUse(rand), 0, 2);
		world.setBlock(i + 7, j + 12, k + 4, pickBlockToUse(rand), 0, 2);
		world.setBlock(i + 7, j + 12, k + 5, pickBlockToUse(rand), 0, 2);
		world.setBlock(i + 7, j + 12, k + 6, pickBlockToUse(rand), 0, 2);
		world.setBlock(i + 7, j + 12, k + 7, pickBlockToUse(rand), 0, 2);
		world.setBlock(i + 7, j + 12, k + 8, pickBlockToUse(rand), 0, 2);
		world.setBlock(i + 7, j + 13, k + 1, pickBlockToUse(rand), 0, 2);
		world.setBlock(i + 7, j + 13, k + 2, pickBlockToUse(rand), 0, 2);
		world.setBlock(i + 7, j + 13, k + 3, pickBlockToUse(rand), 0, 2);
		world.setBlock(i + 7, j + 13, k + 4, pickBlockToUse(rand), 0, 2);
		world.setBlock(i + 7, j + 13, k + 5, pickBlockToUse(rand), 0, 2);
		world.setBlock(i + 7, j + 13, k + 6, pickBlockToUse(rand), 0, 2);
		world.setBlock(i + 7, j + 13, k + 7, pickBlockToUse(rand), 0, 2);
		world.setBlock(i + 7, j + 13, k + 8, pickBlockToUse(rand), 0, 2);
		world.setBlock(i + 8, j + 4, k + 1, pickBlockToUse(rand), 0, 2);
		world.setBlock(i + 8, j + 4, k + 2, pickBlockToUse(rand), 0, 2);
		world.setBlock(i + 8, j + 4, k + 3, pickBlockToUse(rand), 0, 2);
		world.setBlock(i + 8, j + 4, k + 4, pickBlockToUse(rand), 0, 2);
		world.setBlock(i + 8, j + 4, k + 5, pickBlockToUse(rand), 0, 2);
		world.setBlock(i + 8, j + 4, k + 6, pickBlockToUse(rand), 0, 2);
		world.setBlock(i + 8, j + 4, k + 7, pickBlockToUse(rand), 0, 2);
		world.setBlock(i + 8, j + 4, k + 8, pickBlockToUse(rand), 0, 2);
		world.setBlock(i + 8, j + 5, k + 1, pickBlockToUse(rand), 0, 2);
		world.setBlock(i + 8, j + 5, k + 2, pickBlockToUse(rand), 0, 2);
		world.setBlock(i + 8, j + 5, k + 3, Blocks.obsidian, 0, 2);
		world.setBlock(i + 8, j + 5, k + 4, pickBlockToUse(rand), 0, 2);
		world.setBlock(i + 8, j + 5, k + 5, pickBlockToUse(rand), 0, 2);
		world.setBlock(i + 8, j + 5, k + 6, Blocks.obsidian, 0, 2);
		world.setBlock(i + 8, j + 5, k + 7, pickBlockToUse(rand), 0, 2);
		world.setBlock(i + 8, j + 5, k + 8, pickBlockToUse(rand), 0, 2);
		world.setBlock(i + 8, j + 6, k + 1, pickBlockToUse(rand), 0, 2);
		world.setBlock(i + 8, j + 6, k + 2, pickBlockToUse(rand), 0, 2);
		world.setBlock(i + 8, j + 6, k + 3, pickBlockToUse(rand), 0, 2);
		world.setBlock(i + 8, j + 6, k + 4, pickBlockToUse(rand), 0, 2);
		world.setBlock(i + 8, j + 6, k + 5, pickBlockToUse(rand), 0, 2);
		world.setBlock(i + 8, j + 6, k + 6, pickBlockToUse(rand), 0, 2);
		world.setBlock(i + 8, j + 6, k + 7, pickBlockToUse(rand), 0, 2);
		world.setBlock(i + 8, j + 6, k + 8, pickBlockToUse(rand), 0, 2);
		world.setBlock(i + 8, j + 7, k + 1, pickBlockToUse(rand), 0, 2);
		world.setBlock(i + 8, j + 7, k + 2, Blocks.iron_block, 0, 2);
		world.setBlock(i + 8, j + 7, k + 3, Blocks.emerald_block, 0, 2);
		world.setBlock(i + 8, j + 7, k + 4, pickBlockToUse(rand), 0, 2);
		world.setBlock(i + 8, j + 7, k + 5, pickBlockToUse(rand), 0, 2);
		world.setBlock(i + 8, j + 7, k + 6, Blocks.emerald_block, 0, 2);
		world.setBlock(i + 8, j + 7, k + 7, Blocks.iron_block, 0, 2);
		world.setBlock(i + 8, j + 7, k + 8, pickBlockToUse(rand), 0, 2);
		world.setBlock(i + 8, j + 8, k + 1, pickBlockToUse(rand), 0, 2);
		world.setBlock(i + 8, j + 8, k + 2, Blocks.obsidian, 0, 2);
		world.setBlock(i + 8, j + 8, k + 3, Blocks.obsidian, 0, 2);
		world.setBlock(i + 8, j + 8, k + 4, Blocks.obsidian, 0, 2);
		world.setBlock(i + 8, j + 8, k + 5, Blocks.obsidian, 0, 2);
		world.setBlock(i + 8, j + 8, k + 6, Blocks.obsidian, 0, 2);
		world.setBlock(i + 8, j + 8, k + 7, Blocks.obsidian, 0, 2);
		world.setBlock(i + 8, j + 8, k + 8, pickBlockToUse(rand), 0, 2);
		world.setBlock(i + 8, j + 9, k + 1, pickBlockToUse(rand), 0, 2);
		world.setBlock(i + 8, j + 9, k + 2, pickBlockToUse(rand), 0, 2);
		world.setBlock(i + 8, j + 9, k + 3, pickBlockToUse(rand), 0, 2);
		world.setBlock(i + 8, j + 9, k + 4, pickBlockToUse(rand), 0, 2);
		world.setBlock(i + 8, j + 9, k + 5, pickBlockToUse(rand), 0, 2);
		world.setBlock(i + 8, j + 9, k + 6, pickBlockToUse(rand), 0, 2);
		world.setBlock(i + 8, j + 9, k + 7, pickBlockToUse(rand), 0, 2);
		world.setBlock(i + 8, j + 9, k + 8, pickBlockToUse(rand), 0, 2);
		world.setBlock(i + 8, j + 10, k + 1, pickBlockToUse(rand), 0, 2);
		world.setBlock(i + 8, j + 10, k + 2, pickBlockToUse(rand), 0, 2);
		world.setBlock(i + 8, j + 10, k + 3, pickBlockToUse(rand), 0, 2);
		world.setBlock(i + 8, j + 10, k + 4, pickBlockToUse(rand), 0, 2);
		world.setBlock(i + 8, j + 10, k + 5, pickBlockToUse(rand), 0, 2);
		world.setBlock(i + 8, j + 10, k + 6, pickBlockToUse(rand), 0, 2);
		world.setBlock(i + 8, j + 10, k + 7, pickBlockToUse(rand), 0, 2);
		world.setBlock(i + 8, j + 10, k + 8, pickBlockToUse(rand), 0, 2);
		world.setBlock(i + 8, j + 11, k + 1, pickBlockToUse(rand), 0, 2);
		world.setBlock(i + 8, j + 11, k + 2, pickBlockToUse(rand), 0, 2);
		world.setBlock(i + 8, j + 11, k + 3, pickBlockToUse(rand), 0, 2);
		world.setBlock(i + 8, j + 11, k + 4, pickBlockToUse(rand), 0, 2);
		world.setBlock(i + 8, j + 11, k + 5, pickBlockToUse(rand), 0, 2);
		world.setBlock(i + 8, j + 11, k + 6, pickBlockToUse(rand), 0, 2);
		world.setBlock(i + 8, j + 11, k + 7, pickBlockToUse(rand), 0, 2);
		world.setBlock(i + 8, j + 11, k + 8, pickBlockToUse(rand), 0, 2);
		world.setBlock(i + 8, j + 12, k + 1, pickBlockToUse(rand), 0, 2);
		world.setBlock(i + 8, j + 12, k + 2, pickBlockToUse(rand), 0, 2);
		world.setBlock(i + 8, j + 12, k + 3, pickBlockToUse(rand), 0, 2);
		world.setBlock(i + 8, j + 12, k + 4, pickBlockToUse(rand), 0, 2);
		world.setBlock(i + 8, j + 12, k + 5, pickBlockToUse(rand), 0, 2);
		world.setBlock(i + 8, j + 12, k + 6, pickBlockToUse(rand), 0, 2);
		world.setBlock(i + 8, j + 12, k + 7, pickBlockToUse(rand), 0, 2);
		world.setBlock(i + 8, j + 12, k + 8, pickBlockToUse(rand), 0, 2);
		world.setBlock(i + 8, j + 13, k + 1, pickBlockToUse(rand), 0, 2);
		world.setBlock(i + 8, j + 13, k + 2, pickBlockToUse(rand), 0, 2);
		world.setBlock(i + 8, j + 13, k + 3, pickBlockToUse(rand), 0, 2);
		world.setBlock(i + 8, j + 13, k + 4, pickBlockToUse(rand), 0, 2);
		world.setBlock(i + 8, j + 13, k + 5, pickBlockToUse(rand), 0, 2);
		world.setBlock(i + 8, j + 13, k + 6, pickBlockToUse(rand), 0, 2);
		world.setBlock(i + 8, j + 13, k + 7, pickBlockToUse(rand), 0, 2);
		world.setBlock(i + 8, j + 13, k + 8, pickBlockToUse(rand), 0, 2);
		world.setBlock(i + 9, j + 3, k + 4, pickBlockToUse(rand), 0, 2);
		world.setBlock(i + 9, j + 3, k + 5, pickBlockToUse(rand), 0, 2);
		world.setBlock(i + 9, j + 4, k + 4, pickBlockToUse(rand), 0, 2);
		world.setBlock(i + 9, j + 4, k + 5, pickBlockToUse(rand), 0, 2);
		world.setBlock(i + 9, j + 5, k + 4, pickBlockToUse(rand), 0, 2);
		world.setBlock(i + 9, j + 5, k + 5, pickBlockToUse(rand), 0, 2);
		world.setBlock(i + 9, j + 6, k + 4, pickBlockToUse(rand), 0, 2);
		world.setBlock(i + 9, j + 6, k + 5, pickBlockToUse(rand), 0, 2);
		
		return true;
	}
	
	public Block pickBlockToUse(Random rand) {
		int block = rand.nextInt(2);
		if(block == 0) {
			return Blocks.stone;
		} else if(block == 1) {
			int block2 = rand.nextInt(4);
			if(block2 == 0) {
				return Blocks.mossy_cobblestone;
			} else {
				return Blocks.cobblestone;
			}
		}
		return Blocks.stone;
	}
}